<mujoco model="electric">
    <!--  Copyright © 2018, Roboti LLC

          This file is licensed under the MuJoCo Resource License (the "License").
          You may not use this file except in compliance with the License.
          You may obtain a copy of the License at

            https://www.roboti.us/resourcelicense.txt
    -->
 <asset>
   <!--												 USB 																-->
	<mesh file="electric_plug_2/untitleduntitledENCHUFE_PLANO_V1_hull_1.stl" name="elec_cable1"  scale="2e-3 2e-3 2e-3"/>
	<mesh file="electric_plug_2/untitleduntitledENCHUFE_PLANO_V1_hull_2.stl" name="elec_cable2"  scale="2e-3 2e-3 2e-3"/>
	<mesh file="electric_plug_2/untitleduntitledENCHUFE_PLANO_V1_hull_3.stl" name="elec_cable3"  scale="2e-3 2e-3 2e-3"/>
	<mesh file="electric_plug_2/untitleduntitledENCHUFE_PLANO_V1_hull_4.stl" name="elec_cable4"  scale="2e-3 2e-3 2e-3"/>
	<mesh file="electric_plug_2/untitleduntitledENCHUFE_PLANO_V1_hull_5.stl" name="elec_cable5"  scale="2e-3 2e-3 2e-3"/>
	<mesh file="electric_plug_2/untitleduntitledENCHUFE_PLANO_V1_hull_6.stl" name="elec_cable6"  scale="2e-3 2e-3 2e-3"/>
	<mesh file="electric_plug_2/untitleduntitledENCHUFE_PLANO_V1_hull_7.stl" name="elec_cable7"  scale="2e-3 2e-3 2e-3"/>
	<mesh file="electric_plug_2/untitleduntitledENCHUFE_PLANO_V1_hull_8.stl" name="elec_cable8"  scale="2e-3 2e-3 2e-3"/>
	<mesh file="electric_plug_2/untitleduntitledENCHUFE_PLANO_V1_hull_9.stl" name="elec_cable9"  scale="2e-3 2e-3 2e-3"/>
	<mesh file="electric_plug_2/untitleduntitledENCHUFE_PLANO_V1_hull_10.stl" name="elec_cable10"  scale="2e-3 2e-3 2e-3"/>
	<mesh file="electric_plug_2/untitleduntitledENCHUFE_PLANO_V1_hull_11.stl" name="elec_cable11"  scale="2e-3 2e-3 2e-3"/>
	<mesh file="electric_plug_2/untitleduntitledENCHUFE_PLANO_V1_hull_12.stl" name="elec_cable12"  scale="2e-3 2e-3 2e-3"/>
	<mesh file="electric_plug_2/untitleduntitledENCHUFE_PLANO_V1_hull_13.stl" name="elec_cable13"  scale="2e-3 2e-3 2e-3"/>
	<mesh file="electric_plug_2/untitleduntitledENCHUFE_PLANO_V1_hull_14.stl" name="elec_cable14"  scale="2e-3 2e-3 2e-3"/>
	<mesh file="electric_plug_2/untitleduntitledENCHUFE_PLANO_V1_hull_15.stl" name="elec_cable15"  scale="2e-3 2e-3 2e-3"/>
	<mesh file="electric_plug_2/untitleduntitledENCHUFE_PLANO_V1_hull_16.stl" name="elec_cable16"  scale="2e-3 2e-3 2e-3"/>
	<mesh file="electric_plug_2/untitleduntitledENCHUFE_PLANO_V1_hull_17.stl" name="elec_cable17"  scale="2e-3 2e-3 2e-3"/>
	<mesh file="electric_plug_2/untitleduntitledENCHUFE_PLANO_V1_hull_18.stl" name="elec_cable18"  scale="2e-3 2e-3 2e-3"/>
	<mesh file="electric_plug_2/untitleduntitledENCHUFE_PLANO_V1_hull_19.stl" name="elec_cable19"  scale="2e-3 2e-3 2e-3"/>
	<mesh file="electric_plug_2/untitleduntitledENCHUFE_PLANO_V1_hull_20.stl" name="elec_cable20"  scale="2e-3 2e-3 2e-3"/>
	<mesh file="electric_plug_2/untitleduntitledENCHUFE_PLANO_V1_hull_21.stl" name="elec_cable21"  scale="2e-3 2e-3 2e-3"/>
	<mesh file="electric_plug_2/untitleduntitledENCHUFE_PLANO_V1_hull_22.stl" name="elec_cable22"  scale="2e-3 2e-3 2e-3"/>
	<mesh file="electric_plug_2/untitleduntitledENCHUFE_PLANO_V1_hull_23.stl" name="elec_cable23"  scale="2e-3 2e-3 2e-3"/>
	
	 
	</asset>
	
    <worldbody>

<body>
		<body name="elec1" pos="0.016 0.009 0.016">
			 <!--											USB															-->
		<geom pos="0 0 -0.03" mesh="elec_cable1" type="mesh" solimp="0.998 0.998 0.001" solref="0.001 1" density="6700" friction="0.95 0.3 0.1" material="metal" group="1" condim="4"   zaxis="0 1 0"/>
		<geom pos="0 0 -0.03" mesh="elec_cable2" type="mesh" solimp="0.998 0.998 0.001" solref="0.001 1" density="6700" friction="0.95 0.3 0.1" material="metal" group="1" condim="4"  zaxis="0 1 0" />
		 <geom pos="0 0 -0.03" mesh="elec_cable3" type="mesh" solimp="0.998 0.998 0.001" solref="0.001 1" density="6700" friction="0.95 0.3 0.1" material="metal" group="1" condim="4"  zaxis="0 1 0" />
		<geom pos="0 0 -0.03" mesh="elec_cable4" type="mesh" solimp="0.998 0.998 0.001" solref="0.001 1" density="6700" friction="0.95 0.3 0.1" material="metal" group="1" condim="4"  zaxis="0 1 0" />
		<geom pos="0 0 -0.03" mesh="elec_cable5" type="mesh" solimp="0.998 0.998 0.001" solref="0.001 1" density="6700" friction="0.95 0.3 0.1" material="metal" group="1" condim="4"   zaxis="0 1 0"/>
		<geom pos="0 0 -0.03" mesh="elec_cable6" type="mesh" solimp="0.998 0.998 0.001" solref="0.001 1" density="6700" friction="0.95 0.3 0.1" material="metal" group="1" condim="4"   zaxis="0 1 0"/>
		<geom pos="0 0 -0.03" mesh="elec_cable7" type="mesh" solimp="0.998 0.998 0.001" solref="0.001 1" density="6700" friction="0.95 0.3 0.1" material="metal" group="1" condim="4"   zaxis="0 1 0"/>
		<geom pos="0 0 -0.03" mesh="elec_cable8" type="mesh" solimp="0.998 0.998 0.001" solref="0.001 1" density="6700" friction="0.95 0.3 0.1" material="metal" group="1" condim="4"   zaxis="0 1 0"/>
		<geom pos="0 0 -0.03" mesh="elec_cable9" type="mesh" solimp="0.998 0.998 0.001" solref="0.001 1" density="6700" friction="0.95 0.3 0.1" material="metal" group="1" condim="4"  zaxis="0 1 0" />
		 <geom pos="0 0 -0.03" mesh="elec_cable10" type="mesh" solimp="0.998 0.998 0.001" solref="0.001 1" density="6700" friction="0.95 0.3 0.1" material="metal" group="1" condim="4"  zaxis="0 1 0" />
		<geom pos="0 0 -0.03" mesh="elec_cable11" type="mesh" solimp="0.998 0.998 0.001" solref="0.001 1" density="6700" friction="0.95 0.3 0.1" material="metal" group="1" condim="4"  zaxis="0 1 0" />
		<geom pos="0 0 -0.03" mesh="elec_cable12" type="mesh" solimp="0.998 0.998 0.001" solref="0.001 1" density="6700" friction="0.95 0.3 0.1" material="metal" group="1" condim="4"   zaxis="0 1 0"/>
		<geom pos="0 0 -0.03" mesh="elec_cable13" type="mesh" solimp="0.998 0.998 0.001" solref="0.001 1" density="6700" friction="0.95 0.3 0.1" material="metal" group="1" condim="4"   zaxis="0 1 0"/>
		<geom pos="0 0 -0.03" mesh="elec_cable14" type="mesh" solimp="0.998 0.998 0.001" solref="0.001 1" density="6700" friction="0.95 0.3 0.1" material="metal" group="1" condim="4"   zaxis="0 1 0"/>
		<geom pos="0 0 -0.03" mesh="elec_cable15" type="mesh" solimp="0.998 0.998 0.001" solref="0.001 1" density="6700" friction="0.95 0.3 0.1" material="metal" group="1" condim="4"   zaxis="0 1 0"/>
		<geom pos="0 0 -0.03" mesh="elec_cable16" type="mesh" solimp="0.998 0.998 0.001" solref="0.001 1" density="6700" friction="0.95 0.3 0.1" material="metal" group="1" condim="4"  zaxis="0 1 0" />
		 <geom pos="0 0 -0.03" mesh="elec_cable17" type="mesh" solimp="0.998 0.998 0.001" solref="0.001 1" density="6700" friction="0.95 0.3 0.1" material="metal" group="1" condim="4"  zaxis="0 1 0" />
		<geom pos="0 0 -0.03" mesh="elec_cable18" type="mesh" solimp="0.998 0.998 0.001" solref="0.001 1" density="6700" friction="0.95 0.3 0.1" material="metal" group="1" condim="4"  zaxis="0 1 0" />
		<geom pos="0 0 -0.03" mesh="elec_cable19" type="mesh" solimp="0.998 0.998 0.001" solref="0.001 1" density="6700" friction="0.95 0.3 0.1" material="metal" group="1" condim="4"   zaxis="0 1 0"/>
		<geom pos="0 0 -0.03" mesh="elec_cable20" type="mesh" solimp="0.998 0.998 0.001" solref="0.001 1" density="6700" friction="0.95 0.3 0.1" material="metal" group="1" condim="4"   zaxis="0 1 0"/>
		<geom pos="0 0 -0.03" mesh="elec_cable21" type="mesh" solimp="0.998 0.998 0.001" solref="0.001 1" density="6700" friction="0.95 0.3 0.1" material="metal" group="1" condim="4"   zaxis="0 1 0"/>
		<geom pos="0 0 -0.03" mesh="elec_cable22" type="mesh" solimp="0.998 0.998 0.001" solref="0.001 1" density="6700" friction="0.95 0.3 0.1" material="metal" group="1" condim="4"   zaxis="0 1 0"/>
		<geom pos="0 0 -0.03" mesh="elec_cable23" type="mesh" solimp="0.998 0.998 0.001" solref="0.001 1" density="6700" friction="0.95 0.3 0.1" material="metal" group="1" condim="4"  zaxis="0 1 0" />
		
		<joint axis="1 0 0" name="elecx1" type="slide" /><joint axis="0 1 0" name="elecy1" type="slide" /><joint axis="0 0 1" name="elecz1" type="slide" />
		<site rgba="0 0 0 0" size="0.005" pos="0 0 -0.03" name="cube_site"/>
		</body>
		
		
		
		



    </body> 

    </worldbody>
</mujoco>
