<mujoco model="ethernet">
    <!--  Copyright © 2018, Roboti LLC

          This file is licensed under the MuJoCo Resource License (the "License").
          You may not use this file except in compliance with the License.
          You may obtain a copy of the License at

            https://www.roboti.us/resourcelicense.txt
    -->
 <asset>
   <!---													 USB 												-->
    <mesh file="ethernet_cable/untitleduntitledethernetUnsealed_Ethernet_Cable_Receptacle_Endether_000.stl" name="ether_cable_1"  scale="1.9e-3 1.9e-3 1.9e-3"/>
	<mesh file="ethernet_cable/untitleduntitledethernetUnsealed_Ethernet_Cable_Receptacle_Endether_001.stl" name="ether_cable_2"  scale="1.9e-3 1.9e-3 1.9e-3"/>
	<mesh file="ethernet_cable/untitleduntitledethernetUnsealed_Ethernet_Cable_Receptacle_Endether_002.stl" name="ether_cable_3"  scale="1.9e-3 1.9e-3 1.9e-3"/>
	<mesh file="ethernet_cable/untitleduntitledethernetUnsealed_Ethernet_Cable_Receptacle_Endether_003.stl" name="ether_cable_4"  scale="1.9e-3 1.9e-3 1.9e-3"/>
	<mesh file="ethernet_cable/untitleduntitledethernetUnsealed_Ethernet_Cable_Receptacle_Endether_004.stl" name="ether_cable_5"  scale="1.9e-3 1.9e-3 1.9e-3"/>
	<mesh file="ethernet_cable/untitleduntitledethernetUnsealed_Ethernet_Cable_Receptacle_Endether_005.stl" name="ether_cable_6"  scale="1.9e-3 1.9e-3 1.9e-3"/>
	<mesh file="ethernet_cable/untitleduntitledethernetUnsealed_Ethernet_Cable_Receptacle_Endether_006.stl" name="ether_cable_7"  scale="1.9e-3 1.9e-3 1.9e-3"/>
	 <mesh file="ethernet_cable/untitleduntitledethernetUnsealed_Ethernet_Cable_Receptacle_Endether_007.stl" name="ether_cable_8"  scale="1.9e-3 1.9e-3 1.9e-3"/>
	<mesh file="ethernet_cable/untitleduntitledethernetUnsealed_Ethernet_Cable_Receptacle_Endether_008.stl" name="ether_cable_9"  scale="1.9e-3 1.9e-3 1.9e-3"/>
	<mesh file="ethernet_cable/untitleduntitledethernetUnsealed_Ethernet_Cable_Receptacle_Endether_009.stl" name="ether_cable_10"  scale="1.9e-3 1.9e-3 1.9e-3"/>
	<mesh file="ethernet_cable/untitleduntitledethernetUnsealed_Ethernet_Cable_Receptacle_Endether_010.stl" name="ether_cable_11"  scale="1.9e-3 1.9e-3 1.9e-3"/>
	<mesh file="ethernet_cable/untitleduntitledethernetUnsealed_Ethernet_Cable_Receptacle_Endether_011.stl" name="ether_cable_12"  scale="1.9e-3 1.9e-3 1.9e-3"/>
	<mesh file="ethernet_cable/untitleduntitledethernetUnsealed_Ethernet_Cable_Receptacle_Endether_012.stl" name="ether_cable_13"  scale="1.9e-3 1.9e-3 1.9e-3"/>
	<mesh file="ethernet_cable/untitleduntitledethernetUnsealed_Ethernet_Cable_Receptacle_Endether_013.stl" name="ether_cable_14" scale="1.9e-3 1.9e-3 1.9e-3"/>
	<mesh file="ethernet_cable/untitleduntitledethernetUnsealed_Ethernet_Cable_Receptacle_Endether_014.stl" name="ether_cable_15"  scale="1.9e-3 1.9e-3 1.9e-3"/>
	<mesh file="ethernet_cable/untitleduntitledethernetUnsealed_Ethernet_Cable_Receptacle_Endether_015.stl" name="ether_cable_16"  scale="1.9e-3 1.9e-3 1.9e-3"/>
	<mesh file="ethernet_cable/untitleduntitledethernetUnsealed_Ethernet_Cable_Receptacle_Endether_016.stl" name="ether_cable_17"  scale="1.9e-3 1.9e-3 1.9e-3"/>
	<mesh file="ethernet_cable/untitleduntitledethernetUnsealed_Ethernet_Cable_Receptacle_Endether_017.stl" name="ether_cable_18"  scale="1.9e-3 1.9e-3 1.9e-3"/>
	<mesh file="ethernet_cable/untitleduntitledethernetUnsealed_Ethernet_Cable_Receptacle_Endether_018.stl" name="ether_cable_19"  scale="1.9e-3 1.9e-3 1.9e-3"/>
	<mesh file="ethernet_cable/untitleduntitledethernetUnsealed_Ethernet_Cable_Receptacle_Endether_019.stl" name="ether_cable_20"  scale="1.9e-3 1.9e-3 1.9e-3"/>
	<mesh file="ethernet_cable/untitleduntitledethernetUnsealed_Ethernet_Cable_Receptacle_Endether_020.stl" name="ether_cable_21"  scale="1.9e-3 1.9e-3 1.9e-3"/>
	<mesh file="ethernet_cable/untitleduntitledethernetUnsealed_Ethernet_Cable_Receptacle_Endether_021.stl" name="ether_cable_22"  scale="1.9e-3 1.9e-3 1.9e-3"/>
	<mesh file="ethernet_cable/untitleduntitledethernetUnsealed_Ethernet_Cable_Receptacle_Endether_022.stl" name="ether_cable_23"  scale="1.9e-3 1.9e-3 1.9e-3"/>
	<mesh file="ethernet_cable/untitleduntitledethernetUnsealed_Ethernet_Cable_Receptacle_Endether_023.stl" name="ether_cable_24"  scale="1.9e-3 1.9e-3 1.9e-3"/>
	
	 
	</asset>
	
    <worldbody>

<body>
		<body name="ether1" pos="-0.097 -0.022 -0.024">
			 <!--											  USB														-->
		<geom pos="0 0 -0.03" mesh="ether_cable_1" type="mesh" solimp="0.998 0.998 0.001" solref="0.001 1" density="6700" friction="0.95 0.3 0.1" material="metal" group="1" condim="4"   zaxis="0 1 0"/>
		<geom pos="0 0 -0.03" mesh="ether_cable_2" type="mesh" solimp="0.998 0.998 0.001" solref="0.001 1" density="6700" friction="0.95 0.3 0.1" material="metal" group="1" condim="4"  zaxis="0 1 0" />
		 <geom pos="0 0 -0.03" mesh="ether_cable_3" type="mesh" solimp="0.998 0.998 0.001" solref="0.001 1" density="6700" friction="0.95 0.3 0.1" material="metal" group="1" condim="4"  zaxis="0 1 0" />
		<geom pos="0 0 -0.03" mesh="ether_cable_4" type="mesh" solimp="0.998 0.998 0.001" solref="0.001 1" density="6700" friction="0.95 0.3 0.1" material="metal" group="1" condim="4"  zaxis="0 1 0" />
		<geom pos="0 0 -0.03" mesh="ether_cable_5" type="mesh" solimp="0.998 0.998 0.001" solref="0.001 1" density="6700" friction="0.95 0.3 0.1" material="metal" group="1" condim="4"   zaxis="0 1 0"/>
		<geom pos="0 0 -0.03" mesh="ether_cable_6" type="mesh" solimp="0.998 0.998 0.001" solref="0.001 1" density="6700" friction="0.95 0.3 0.1" material="metal" group="1" condim="4"   zaxis="0 1 0"/>
		<geom pos="0 0 -0.03" mesh="ether_cable_7" type="mesh" solimp="0.998 0.998 0.001" solref="0.001 1" density="6700" friction="0.95 0.3 0.1" material="metal" group="1" condim="4"   zaxis="0 1 0"/>
		<geom pos="0 0 -0.03" mesh="ether_cable_8" type="mesh" solimp="0.998 0.998 0.001" solref="0.001 1" density="6700" friction="0.95 0.3 0.1" material="metal" group="1" condim="4"   zaxis="0 1 0"/>
		<geom pos="0 0 -0.03" mesh="ether_cable_9" type="mesh" solimp="0.998 0.998 0.001" solref="0.001 1" density="6700" friction="0.95 0.3 0.1" material="metal" group="1" condim="4"  zaxis="0 1 0" />
		 <geom pos="0 0 -0.03" mesh="ether_cable_10" type="mesh" solimp="0.998 0.998 0.001" solref="0.001 1" density="6700" friction="0.95 0.3 0.1" material="metal" group="1" condim="4"  zaxis="0 1 0" />
		<geom pos="0 0 -0.03" mesh="ether_cable_11" type="mesh" solimp="0.998 0.998 0.001" solref="0.001 1" density="6700" friction="0.95 0.3 0.1" material="metal" group="1" condim="4"  zaxis="0 1 0" />
		<geom pos="0 0 -0.03" mesh="ether_cable_12" type="mesh" solimp="0.998 0.998 0.001" solref="0.001 1" density="6700" friction="0.95 0.3 0.1" material="metal" group="1" condim="4"   zaxis="0 1 0"/>
		<geom pos="0 0 -0.03" mesh="ether_cable_13" type="mesh" solimp="0.998 0.998 0.001" solref="0.001 1" density="6700" friction="0.95 0.3 0.1" material="metal" group="1" condim="4"   zaxis="0 1 0"/>
		<geom pos="0 0 -0.03" mesh="ether_cable_14" type="mesh" solimp="0.998 0.998 0.001" solref="0.001 1" density="6700" friction="0.95 0.3 0.1" material="metal" group="1" condim="4"   zaxis="0 1 0"/>
		<geom pos="0 0 -0.03" mesh="ether_cable_15" type="mesh" solimp="0.998 0.998 0.001" solref="0.001 1" density="6700" friction="0.95 0.3 0.1" material="metal" group="1" condim="4"   zaxis="0 1 0"/>
		<geom pos="0 0 -0.03" mesh="ether_cable_16" type="mesh" solimp="0.998 0.998 0.001" solref="0.001 1" density="6700" friction="0.95 0.3 0.1" material="metal" group="1" condim="4"  zaxis="0 1 0" />
		 <geom pos="0 0 -0.03" mesh="ether_cable_17" type="mesh" solimp="0.998 0.998 0.001" solref="0.001 1" density="6700" friction="0.95 0.3 0.1" material="metal" group="1" condim="4"  zaxis="0 1 0" />
		<geom pos="0 0 -0.03" mesh="ether_cable_18" type="mesh" solimp="0.998 0.998 0.001" solref="0.001 1" density="6700" friction="0.95 0.3 0.1" material="metal" group="1" condim="4"  zaxis="0 1 0" />
		<geom pos="0 0 -0.03" mesh="ether_cable_19" type="mesh" solimp="0.998 0.998 0.001" solref="0.001 1" density="6700" friction="0.95 0.3 0.1" material="metal" group="1" condim="4"   zaxis="0 1 0"/>
		<geom pos="0 0 -0.03" mesh="ether_cable_20" type="mesh" solimp="0.998 0.998 0.001" solref="0.001 1" density="6700" friction="0.95 0.3 0.1" material="metal" group="1" condim="4"   zaxis="0 1 0"/>
		<geom pos="0 0 -0.03" mesh="ether_cable_21" type="mesh" solimp="0.998 0.998 0.001" solref="0.001 1" density="6700" friction="0.95 0.3 0.1" material="metal" group="1" condim="4"   zaxis="0 1 0"/>
		<geom pos="0 0 -0.03" mesh="ether_cable_22" type="mesh" solimp="0.998 0.998 0.001" solref="0.001 1" density="6700" friction="0.95 0.3 0.1" material="metal" group="1" condim="4"   zaxis="0 1 0"/>
		<geom pos="0 0 -0.03" mesh="ether_cable_23" type="mesh" solimp="0.998 0.998 0.001" solref="0.001 1" density="6700" friction="0.95 0.3 0.1" material="metal" group="1" condim="4"  zaxis="0 1 0" />
		 <geom pos="0 0 -0.03" mesh="ether_cable_24" type="mesh" solimp="0.998 0.998 0.001" solref="0.001 1" density="6700" friction="0.95 0.3 0.1" material="metal" group="1" condim="4"  zaxis="0 1 0" />
		
		<joint axis="1 0 0" name="etherx1" type="slide" /><joint axis="0 1 0" name="ethery1" type="slide" /><joint axis="0 0 1" name="etherz1" type="slide" />
		</body>
		
		<body name="ether12" pos="-0.097 -0.010 -0.024">
			 <!--												  USB														-->
		<geom pos="0 0 -0.03" mesh="ether_cable_1" type="mesh" solimp="0.998 0.998 0.001" solref="0.001 1" density="6700" friction="0.95 0.3 0.1" material="metal" group="1" condim="4"   zaxis="0 1 0"/>
		<geom pos="0 0 -0.03" mesh="ether_cable_2" type="mesh" solimp="0.998 0.998 0.001" solref="0.001 1" density="6700" friction="0.95 0.3 0.1" material="metal" group="1" condim="4"  zaxis="0 1 0" />
		 <geom pos="0 0 -0.03" mesh="ether_cable_3" type="mesh" solimp="0.998 0.998 0.001" solref="0.001 1" density="6700" friction="0.95 0.3 0.1" material="metal" group="1" condim="4"  zaxis="0 1 0" />
		<geom pos="0 0 -0.03" mesh="ether_cable_4" type="mesh" solimp="0.998 0.998 0.001" solref="0.001 1" density="6700" friction="0.95 0.3 0.1" material="metal" group="1" condim="4"  zaxis="0 1 0" />
		<geom pos="0 0 -0.03" mesh="ether_cable_5" type="mesh" solimp="0.998 0.998 0.001" solref="0.001 1" density="6700" friction="0.95 0.3 0.1" material="metal" group="1" condim="4"   zaxis="0 1 0"/>
		<geom pos="0 0 -0.03" mesh="ether_cable_6" type="mesh" solimp="0.998 0.998 0.001" solref="0.001 1" density="6700" friction="0.95 0.3 0.1" material="metal" group="1" condim="4"   zaxis="0 1 0"/>
		<geom pos="0 0 -0.03" mesh="ether_cable_7" type="mesh" solimp="0.998 0.998 0.001" solref="0.001 1" density="6700" friction="0.95 0.3 0.1" material="metal" group="1" condim="4"   zaxis="0 1 0"/>
		<geom pos="0 0 -0.03" mesh="ether_cable_8" type="mesh" solimp="0.998 0.998 0.001" solref="0.001 1" density="6700" friction="0.95 0.3 0.1" material="metal" group="1" condim="4"   zaxis="0 1 0"/>
		<geom pos="0 0 -0.03" mesh="ether_cable_9" type="mesh" solimp="0.998 0.998 0.001" solref="0.001 1" density="6700" friction="0.95 0.3 0.1" material="metal" group="1" condim="4"  zaxis="0 1 0" />
		 <geom pos="0 0 -0.03" mesh="ether_cable_10" type="mesh" solimp="0.998 0.998 0.001" solref="0.001 1" density="6700" friction="0.95 0.3 0.1" material="metal" group="1" condim="4"  zaxis="0 1 0" />
		<geom pos="0 0 -0.03" mesh="ether_cable_11" type="mesh" solimp="0.998 0.998 0.001" solref="0.001 1" density="6700" friction="0.95 0.3 0.1" material="metal" group="1" condim="4"  zaxis="0 1 0" />
		<geom pos="0 0 -0.03" mesh="ether_cable_12" type="mesh" solimp="0.998 0.998 0.001" solref="0.001 1" density="6700" friction="0.95 0.3 0.1" material="metal" group="1" condim="4"   zaxis="0 1 0"/>
		<geom pos="0 0 -0.03" mesh="ether_cable_13" type="mesh" solimp="0.998 0.998 0.001" solref="0.001 1" density="6700" friction="0.95 0.3 0.1" material="metal" group="1" condim="4"   zaxis="0 1 0"/>
		<geom pos="0 0 -0.03" mesh="ether_cable_14" type="mesh" solimp="0.998 0.998 0.001" solref="0.001 1" density="6700" friction="0.95 0.3 0.1" material="metal" group="1" condim="4"   zaxis="0 1 0"/>
		<geom pos="0 0 -0.03" mesh="ether_cable_15" type="mesh" solimp="0.998 0.998 0.001" solref="0.001 1" density="6700" friction="0.95 0.3 0.1" material="metal" group="1" condim="4"   zaxis="0 1 0"/>
		<geom pos="0 0 -0.03" mesh="ether_cable_16" type="mesh" solimp="0.998 0.998 0.001" solref="0.001 1" density="6700" friction="0.95 0.3 0.1" material="metal" group="1" condim="4"  zaxis="0 1 0" />
		 <geom pos="0 0 -0.03" mesh="ether_cable_17" type="mesh" solimp="0.998 0.998 0.001" solref="0.001 1" density="6700" friction="0.95 0.3 0.1" material="metal" group="1" condim="4"  zaxis="0 1 0" />
		<geom pos="0 0 -0.03" mesh="ether_cable_18" type="mesh" solimp="0.998 0.998 0.001" solref="0.001 1" density="6700" friction="0.95 0.3 0.1" material="metal" group="1" condim="4"  zaxis="0 1 0" />
		<geom pos="0 0 -0.03" mesh="ether_cable_19" type="mesh" solimp="0.998 0.998 0.001" solref="0.001 1" density="6700" friction="0.95 0.3 0.1" material="metal" group="1" condim="4"   zaxis="0 1 0"/>
		<geom pos="0 0 -0.03" mesh="ether_cable_20" type="mesh" solimp="0.998 0.998 0.001" solref="0.001 1" density="6700" friction="0.95 0.3 0.1" material="metal" group="1" condim="4"   zaxis="0 1 0"/>
		<geom pos="0 0 -0.03" mesh="ether_cable_21" type="mesh" solimp="0.998 0.998 0.001" solref="0.001 1" density="6700" friction="0.95 0.3 0.1" material="metal" group="1" condim="4"   zaxis="0 1 0"/>
		<geom pos="0 0 -0.03" mesh="ether_cable_22" type="mesh" solimp="0.998 0.998 0.001" solref="0.001 1" density="6700" friction="0.95 0.3 0.1" material="metal" group="1" condim="4"   zaxis="0 1 0"/>
		<geom pos="0 0 -0.03" mesh="ether_cable_23" type="mesh" solimp="0.998 0.998 0.001" solref="0.001 1" density="6700" friction="0.95 0.3 0.1" material="metal" group="1" condim="4"  zaxis="0 1 0" />
		 <geom pos="0 0 -0.03" mesh="ether_cable_24" type="mesh" solimp="0.998 0.998 0.001" solref="0.001 1" density="6700" friction="0.95 0.3 0.1" material="metal" group="1" condim="4"  zaxis="0 1 0" />

		
		<joint axis="1 0 0" name="etherx2" type="slide" /><joint axis="0 1 0" name="ethery2" type="slide" /><joint axis="0 0 1" name="etherz2" type="slide" />
		</body>





    </body> 

    </worldbody>
</mujoco>
