<mujoco model="plate_hole">

        <!--  <geom pos="0 0 0" size="0.1 0.25 0.02" type="box" rgba="1 0 0 1"/>
        <geom pos="0.3 0 0" size="0.1 0.25 0.02" type="box" rgba="1 0 0 1"/>
        <geom pos="0.15 0.15 0" size="0.05 0.1 0.02" type="box" rgba="1 0 0 1"/>
        <geom pos="0.15 -0.15 0" size="0.05 0.1 0.02" type="box" rgba="1 0 0 1"/>-->
 <asset>
    <mesh file="meshes/object/untitledPlate22Hole5V2_001.stl" name="1"  scale="0.012 0.012 0.02"/>
	
		
			<mesh file="meshes/object/untitledPlate22Hole5V2_002_hull_1.stl" name="3" scale="0.0012 0.0012 0.005" />
			<mesh file="meshes/object/untitledPlate22Hole5V2_002_hull_2.stl" name="4" scale="0.0012 0.0012 0.005" />
			<mesh file="meshes/object/untitledPlate22Hole5V2_002_hull_3.stl" name="5" scale="0.0012 0.0012 0.005 "/>
			<mesh file="meshes/object/untitledPlate22Hole5V2_002_hull_4.stl" name="6" scale="0.0012 0.0012 0.005" />
			<mesh file="meshes/object/untitledPlate22Hole5V2_002_hull_5.stl" name="7"  scale="0.0012 0.0012 0.005"/>
			<mesh file="meshes/object/untitledPlate22Hole5V2_002_hull_6.stl" name="8"  scale="0.0012 0.0012 0.005"/>
			<mesh file="meshes/object/untitledPlate22Hole5V2_002_hull_7.stl" name="9" scale="0.0012 0.0012 0.005" />
			<mesh file="meshes/object/untitledPlate22Hole5V2_002_hull_8.stl" name="10"  scale="0.0012 0.0012 0.005"/>
			<mesh file="meshes/object/untitledPlate22Hole5V2_002_hull_9.stl" name="11"  scale="0.0012 0.0012 0.005"/>
			<mesh file="meshes/object/untitledPlate22Hole5V2_002_hull_10.stl" name="12"  scale="0.0012 0.0012 0.005" />
			<mesh file="meshes/object/untitledPlate22Hole5V2_002_hull_11.stl" name="13"  scale="0.0012 0.0012 0.005"/>
			<mesh file="meshes/object/untitledPlate22Hole5V2_002_hull_12.stl" name="14"  scale="0.0012 0.0012 0.005"/>
			<mesh file="meshes/object/untitledPlate22Hole5V2_002_hull_13.stl" name="15" scale="0.0012 0.0012 0.005" />
			<mesh file="meshes/object/untitledPlate22Hole5V2_002_hull_14.stl" name="16"  scale="0.0012 0.0012 0.005"/>
			<mesh file="meshes/object/untitledPlate22Hole5V2_002_hull_15.stl" name="17"  scale="0.0012 0.0012 0.005"/>

		
			<mesh file="meshes/object/untitledPlate22Hole5V2_003_hull_1.stl" name="20" scale="0.0012 0.0012 0.005" />
			<mesh file="meshes/object/untitledPlate22Hole5V2_003_hull_2.stl" name="21" scale="0.0012 0.0012 0.005" />
			<mesh file="meshes/object/untitledPlate22Hole5V2_003_hull_3.stl" name="22" scale="0.0012 0.0012 0.005 "/>
			<mesh file="meshes/object/untitledPlate22Hole5V2_003_hull_4.stl" name="23" scale="0.0012 0.0012 0.005" />
			
	
	<texture file="../textures/ceramic.png" name="tex-ceramic"/>
    <material name="ceramic" reflectance="0.5" texrepeat="1 1" texture="tex-ceramic" texuniform="true"/>
  </asset>
  
  
  <worldbody>

    <body>
		<body name="collision">
				<geom pos="0 0 -0.05" mesh="1" type="mesh" solimp="0.998 0.998 0.001" solref="0.001 1" density="6700" friction="0.95 0.3 0.1" material="ceramic" group="1" condim="4" rgba="0 1 0 1"  />


		<geom pos="0 0 -0.05" mesh="3" type="mesh" solimp="0.998 0.998 0.001" solref="0.001 1" density="6700" friction="0.95 0.3 0.1" material="ceramic" group="1" condim="4" rgba="0 1 0 1"  />
		<geom pos="0 0 -0.05" mesh="4" type="mesh" solimp="0.998 0.998 0.001" solref="0.001 1" density="6700" friction="0.95 0.3 0.1" material="ceramic" group="1" condim="4" rgba="0 1 0 1"  />
		<geom pos="0 0 -0.05" mesh="5" type="mesh" solimp="0.998 0.998 0.001" solref="0.001 1" density="6700" friction="0.95 0.3 0.1" material="ceramic" group="1" condim="4" rgba="0 1 0 1"  />
		<geom pos="0 0 -0.05" mesh="6" type="mesh" solimp="0.998 0.998 0.001" solref="0.001 1" density="6700" friction="0.95 0.3 0.1" material="ceramic" group="1" condim="4" rgba="0 1 0 1"  />
		<geom pos="0 0 -0.05" mesh="7" type="mesh" solimp="0.998 0.998 0.001" solref="0.001 1" density="6700" friction="0.95 0.3 0.1" material="ceramic" group="1" condim="4" rgba="0 1 0 1"  />
		<geom pos="0 0 -0.05" mesh="8" type="mesh" solimp="0.998 0.998 0.001" solref="0.001 1" density="6700" friction="0.95 0.3 0.1" material="ceramic" group="1" condim="4" rgba="0 1 0 1"  />
		<geom pos="0 0 -0.05" mesh="9" type="mesh" solimp="0.998 0.998 0.001" solref="0.001 1" density="6700" friction="0.95 0.3 0.1" material="ceramic" group="1" condim="4" rgba="0 1 0 1"  />
		<geom pos="0 0 -0.05" mesh="10" type="mesh" solimp="0.998 0.998 0.001" solref="0.001 1" density="6700" friction="0.95 0.3 0.1" material="ceramic" group="1" condim="4" rgba="0 1 0 1"  />
		<geom pos="0 0 -0.05" mesh="11" type="mesh" solimp="0.998 0.998 0.001" solref="0.001 1" density="6700" friction="0.95 0.3 0.1" material="ceramic" group="1" condim="4" rgba="0 1 0 1"  />
		<geom pos="0 0 -0.05" mesh="12" type="mesh" solimp="0.998 0.998 0.001" solref="0.001 1" density="6700" friction="0.95 0.3 0.1" material="ceramic" group="1" condim="4" rgba="0 1 0 1"  />
	    <geom pos="0 0 -0.05" mesh="13" type="mesh" solimp="0.998 0.998 0.001" solref="0.001 1" density="6700" friction="0.95 0.3 0.1" material="ceramic" group="1" condim="4" rgba="0 1 0 1"  />
		<geom pos="0 0 -0.05" mesh="14" type="mesh" solimp="0.998 0.998 0.001" solref="0.001 1" density="6700" friction="0.95 0.3 0.1" material="ceramic" group="1" condim="4" rgba="0 1 0 1"  />
		<geom pos="0 0 -0.05" mesh="15" type="mesh" solimp="0.998 0.998 0.001" solref="0.001 1" density="6700" friction="0.95 0.3 0.1" material="ceramic" group="1" condim="4" rgba="0 1 0 1"  />
		<geom pos="0 0 -0.05" mesh="16" type="mesh" solimp="0.998 0.998 0.001" solref="0.001 1" density="6700" friction="0.95 0.3 0.1" material="ceramic" group="1" condim="4" rgba="0 1 0 1"  />
		<geom pos="0 0 -0.05" mesh="17" type="mesh" solimp="0.998 0.998 0.001" solref="0.001 1" density="6700" friction="0.95 0.3 0.1" material="ceramic" group="1" condim="4" rgba="0 1 0 1"  />
		<geom pos="0 0 -0.05" mesh="20" type="mesh" solimp="0.998 0.998 0.001" solref="0.001 1" density="6700" friction="0.95 0.3 0.1" material="ceramic" group="1" condim="4" rgba="0 1 0 1"  />
		<geom pos="0 0 -0.05" mesh="21" type="mesh" solimp="0.998 0.998 0.001" solref="0.001 1" density="6700" friction="0.95 0.3 0.1" material="ceramic" group="1" condim="4" rgba="0 1 0 1"  />
		<geom pos="0 0 -0.05" mesh="22" type="mesh" solimp="0.998 0.998 0.001" solref="0.001 1" density="6700" friction="0.95 0.3 0.1" material="ceramic" group="1" condim="4" rgba="0 1 0 1"  />
		<geom pos="0 0 -0.05" mesh="23" type="mesh" solimp="0.998 0.998 0.001" solref="0.001 1" density="6700" friction="0.95 0.3 0.1" material="ceramic" group="1" condim="4" rgba="0 1 0 1"  />


		<site name="middle_cylinder" pos="0.012 -0.012 -0.05" size="0.00002 0.00002 0.00002" />

		
		<body name="hole" pos="0.012 -0.012 -0.05">
			<geom density="3000" friction="1.0 0.005 0.0001" group="1" name="cube3"  rgba="1 0 0 1" size="0.0002 0.0002 0.0002" type="box" />
			<joint axis="1 0 0" name="cubex" type="slide" /><joint axis="0 1 0" name="cubey" type="slide" /><joint axis="0 0 1" name="cubez" type="slide" />
		</body>
		

		
		
		</body>

      <body name="visual">

        <!--  <geom pos="0 0 0" size="0.1 0.25 0.02" type="box" rgba="1 0 0 1"/>
        <geom pos="0.3 0 0" size="0.1 0.25 0.02" type="box" rgba="1 0 0 1"/>
        <geom pos="0.15 0.15 0" size="0.05 0.1 0.02" type="box" rgba="1 0 0 1"/>
        <geom pos="0.15 -0.15 0" size="0.05 0.1 0.02" type="box" rgba="1 0 0 1"/>-->
      </body>



      <site rgba="0 0 0 0" size="0.005" pos="0 0 -0.02" name="bottom_site"/>
      <site rgba="0 0 0 0" size="0.005" pos="0 0 0.02" name="top_site"/>
      <site rgba="0 0 0 0" size="0.005" pos="0.25 0.25 0.1" name="horizontal_radius_site"/>
    </body>
  </worldbody>
</mujoco>
